Workbook

Sheet Discrepancy log
A1: Log ID | B1: Review ID | C1: Incident ID | D1: Event date | E1: Field | F1: Recorded code | G1: Recorded title | H1: My code | I1: My title | J1: My acceptable alternates | K1: Relationship between codes | L1: Recorded code in my alternates? | M1: Blind stage inconclusive? | N1: Category | O1: Applicable manual rule (OIICS 3.03) | P1: Reviewer justification | Q1: Narrative (line breaks removed)
A2: D001 | B2: 4 | C2: 2024064855 | D2: 2024-06-03 | E2: Part of body | F2: 523 | G2: Lower leg(s) | H2: 522 | I2: Knee(s) | K2: Same major group (2-digit) | L2: No | M2: No | N2: Potential discrepancy: recorded code conflicts with text | O2: Part rules of selection | P2: Narrative states bite on the back of the knee; recorded lower leg (523). | Q2: An employee was spraying vegetation around power lines where the grass was tall. He was bitten on the back of his knee by a snake. The employee was hospitalized with swelling, pain, and discoloration.
A3: D002 | B3: 20 | C3: 2024010565 | D3: 2024-01-18 | E3: Event/Exposure | F3: 653 | G3: Caught, entangled in running powered equipment — normal operation | H3: 650 | I3: Struck by running powered equipment— unspecified | J3: 659 | K3: Same major group (2-digit) | L3: No | M3: No | N3: Potential discrepancy: recorded code conflicts with text | O3: Event rules of selection | P3: Table-saw blade cutting the thumb is contact with a running blade (650/659), not being caught/entangled (653). | Q3: An employee was using an industrial table saw when it amputated his thumb and caused a severe laceration to his palm.
A4: D003 | B4: 44 | C4: 2024076269 | D4: 2024-07-11 | E4: Secondary source | F4: 6624 | G4: Other constructed surface | H4: 4223 | I4: Pipes, tubes— metal | K4: Different division | L4: No | M4: No | N4: Potential discrepancy: recorded code conflicts with text | O4: Source/Secondary source rule 1 (follow the Event's "Coding interactions"; 990 vs 991) and rule 2 (whole vs part) | P4: Pipe that struck the ladder initiated the event; recorded secondary source is the floor surface. | Q4: On July 11, 2024, an employee was reconnecting two pipes when one of them rolled off the support that was holding it up. It struck the employee's A-frame ladder and they fell 7.5 feet from the ladder to the floor below. The employee suffered a contusion and lacerations and was hospitalized.
A5: D004 | B5: 93 | C5: 2024109397 | D5: 2024-10-08 | E5: Nature | F5: 6121 | G5: Damage to replaced joints | H5: 124 | I5: Fractures | K5: Different division | L5: No | M5: No | N5: Potential discrepancy: recorded code conflicts with text | O5: Nature rules of selection | P5: Recorded 'damage to replaced joints' is not supported by a narrative describing a fracture of the knee after a trip. | Q5: An employee was walking to his car when he tripped over a board that was secured to the floor of the dock area. His left knee struck the cement dock. The employee was hospitalized and required surgery to repair a broken knee.
A6: D005 | B6: 9 | C6: 2024076056 | D6: 2024-07-06 | E6: Event/Exposure | F6: 990 | G6: Event or exposure — unspecified | H6: 2530 | I6: Pedestrian struck by vehicle in nonroadway area— unspecified | J6: 2532, 2531, 655 | K6: Different division | L6: No | M6: No | N6: Potential discrepancy: recorded code less specific | O6: Event rule 1 (code that best describes the harmful incident) | P6: Narrative supports a vehicle (forklift) running over a pedestrian worker; recorded 990 is less specific. | Q6: An employee was working on the sales floor when his right foot was run over by a forklift. The employee sustained a fractured little toe.
A7: D006 | B7: 10 | C7: 2024087970 | D7: 2024-08-27 | E7: Event/Exposure | F7: 990 | G7: Event or exposure — unspecified | H7: 6619 | I7: Injured by object handled by person— n.e.c. | J7: 661, 663, 664, 6612, 6611 | K7: Different division | L7: No | M7: No | N7: Potential discrepancy: recorded code less specific | O7: Event rule 1 (code that best describes the harmful incident) | P7: Narrative supports a specific event (struck by shifting object handled by worker); recorded 990 is less specific. | Q7: An employee was moving metal repair parts from the ground to a vehicle. The metal shifted in transit and amputated the employee's left middle fingertip.
A8: D007 | B8: 13 | C8: 2024032393 | D8: 2024-03-18 | E8: Source | F8: 360 | G8: Special process machinery — unspecified | H8: 3642 | I8: Rollers, calenders, dryers—paper production | J8: 364, 3640 | K8: Same major group (2-digit) | L8: No | M8: No | N8: Potential discrepancy: recorded code less specific | O8: Source/Secondary source rule 1 (follow the Event's "Coding interactions"; 990 vs 991) and rule 2 (whole vs part) | P8: Narrative identifies paper-processing rollers; recorded 360 (special process machinery, unspecified) is less specific. | Q8: An employee was putting paper through the rolls on a machine when their gloved hand became entangled in the rollers. The employee's forearm was pulled into the machine between the belt-driven roller and a hot, steam-heated roller. The employee's right forearm sustained burn injuries that required hospitalization and surgical repair.
A9: D008 | B9: 31 | C9: 2024076773 | D9: 2024-07-25 | E9: Event/Exposure | F9: 650 | G9: Struck by running powered equipment — unspecified | H9: 653 | I9: Caught, entangled in running powered equipment— normal operation | J9: 662, 654 | K9: Same major group (2-digit) | L9: No | M9: No | N9: Potential discrepancy: recorded code less specific | O9: Event rule 1 (code that best describes the harmful incident) | P9: Arm pulled between roller and drum is caught/compressed in running equipment (653); recorded 650 is less specific. | Q9: An employee was threading film through a machine. The film got caught on the casting drum, pulling the film and employee's arm between a roller and the casting drum. The employee sustained a friction burn.
A10: D009 | B10: 31 | C10: 2024076773 | D10: 2024-07-25 | E10: Source | F10: 30 | G10: Machinery — unspecified | H10: 3511 | I10: Casting machinery | J10: 351, 352, 3414, 3640 | K10: Same division only | L10: No | M10: No | N10: Potential discrepancy: recorded code less specific | O10: Source/Secondary source rule 1 (follow the Event's "Coding interactions"; 990 vs 991) and rule 2 (whole vs part) | P10: Narrative identifies a casting drum/film machine; recorded 30 is less specific. | Q10: An employee was threading film through a machine. The film got caught on the casting drum, pulling the film and employee's arm between a roller and the casting drum. The employee sustained a friction burn.
A11: D010 | B11: 33 | C11: 2024021550 | D11: 2024-02-19 | E11: Event/Exposure | F11: 320 | G11: Fire — unspecified | H11: 324 | I11: Vehicle or machinery fire | J11: 323, 320, 325 | K11: Same major group (2-digit) | L11: Yes | M11: No | N11: Potential discrepancy: recorded code less specific | O11: Event rule 1 (code that best describes the harmful incident) | P11: Fire involving a pump suggests machinery fire (324); recorded 320 is less specific. | Q11: A fire involving a vacuum pump in the hospital basement caused an employee to suffer smoke inhalation.
A12: D011 | B12: 43 | C12: 20241211414 | D12: 2024-12-10 | E12: Nature | F12: 189 | G12: Other multiple traumatic injuries — n.e.c. | H12: 1825 | I12: Fractures and burns | J12: 189, 1841, 1531 | K12: Same major group (2-digit) | L12: Yes | M12: No | N12: Potential discrepancy: recorded code less specific | O12: Nature rule 3 (multiple injuries) and rule 4.a | P12: Dislocated/broken shoulder plus burns have a specific combination code (1825); recorded 189 n.e.c. is less specific. | Q12: An employee was on a ladder inside a ceiling grid to strip a live electrical wire. The wire stripper he was holding contacted the live wire, resulting in a shock that caused him to fall from the ladder. The employee suffered a dislocated and broken left shoulder as well as second- and third-degree burns on his left finger.
A13: D012 | B13: 45 | C13: 2024010089 | D13: 2024-01-04 | E13: Source | F13: 350 | G13: Metal, woodworking, and special material machinery — unspecified | H13: 3529 | I13: Bending, rolling, shaping, stamping machinery— n.e.c. | J13: 352, 3520 | K13: Same major group (2-digit) | L13: No | M13: No | N13: Potential discrepancy: recorded code less specific | O13: Source/Secondary source rule 1 (follow the Event's "Coding interactions"; 990 vs 991) and rule 2 (whole vs part) | P13: Triangle roller is a bending/rolling machine (3529); recorded 350 is less specific. | Q13: An employee was feeding a piece of metal into a triangle roller. The roller caught the employee's welding glove and pulled in their left hand, breaking three fingers and causing a degloving injury. The machine was unguarded at the time of the incident.
A14: D013 | B14: 50 | C14: 2024054302 | D14: 2024-05-15 | E14: Part of body | F14: 540 | G14: Foot (feet), toe(s) — unspecified | H14: 541 | I14: Foot (feet)— excluding toes | J14: 540 | K14: Same major group (2-digit) | L14: Yes | M14: No | N14: Potential discrepancy: recorded code less specific | O14: Part rule 1 (highest level of detail supported by the case information) | P14: Narrative states fractured foot; 541 (foot, excluding toes) is supported and more specific than 540. | Q14: An employee was moving a piece of lashing gear obstructing the walkway on a cargo ship when he slipped and fell through a ladder access hatch to the deck below. He sustained a fractured left foot.
A15: D014 | B15: 74 | C15: 20241110591 | D15: 2024-11-13 | E15: Event/Exposure | F15: 990 | G15: Event or exposure — unspecified | H15: 533 | I15: Contact with hot objects or substances | J15: 513, 550 | K15: Different division | L15: No | M15: No | N15: Potential discrepancy: recorded code less specific | O15: Event rule 1 (code that best describes the harmful incident) | P15: Welding burns support contact with hot objects/substances; recorded 990 is less specific. | Q15: A employee was welding and an assistant was handing him welding rods. The welder received burns to his hands and face and was not hospitalized. The assistant received first- and second-degree burns to their hands, neck, and face that required hospitalization.
A16: D015 | B16: 74 | C16: 20241110591 | D16: 2024-11-13 | E16: Source | F16: 990 | G16: Source, secondary source — unspecified | H16: 7181 | I16: Torches— welding, cutting | J16: 718, 3595, 7180 | K16: Different division | L16: No | M16: No | N16: Potential discrepancy: recorded code less specific | O16: Source/Secondary source rule 1 (follow the Event's "Coding interactions"; 990 vs 991) and rule 2 (whole vs part) | P16: Welding torch/rods supported; recorded 990 is less specific. | Q16: A employee was welding and an assistant was handing him welding rods. The welder received burns to his hands and face and was not hospitalized. The assistant received first- and second-degree burns to their hands, neck, and face that required hospitalization.
A17: D016 | B17: 75 | C17: 2024065448 | D17: 2024-06-19 | E17: Event/Exposure | F17: 310 | G17: Explosion — unspecified | H17: 313 | I17: Explosion of pressure vessel, piping, or tire | J17: 642, 319 | K17: Same major group (2-digit) | L17: No | M17: No | N17: Potential discrepancy: recorded code less specific | O17: Event rule 1 (code that best describes the harmful incident) | P17: Air spring burst is a pressure-vessel type explosion (313); recorded 310 is less specific. | Q17: An employee was making an adjustment to the air spring system on a truck when the air spring on the driver's side inflated and exploded. The sudden release of air pressure propelled the employee's head into the truck's frame, resulting in serious injury to their head and hearing.
... A28: D027 | B28: 8 | C28: 2024010693 | D28: 2024-01-23 | E28: Nature | F28: 110 | G28: Injuries to the brain, spinal cord — unspecified | H28: 100 | I28: Traumatic injuries or exposures— unspecified | J28: 110, 1113, 134, 132 | K28: Same division only | L28: Yes | M28: No | N28: Insufficient narrative information | O28: Nature rules of selection | P28: 'Head injury' alone does not specify brain injury; recorded 110 needs detail not in the narrative. | Q28: An employee was walking to the break room when they slipped on a puddle of rain water on the floor and fell. The employee suffered a head injury.
A29: D028 | B29: 8 | C29: 2024010693 | D29: 2024-01-23 | E29: Part of body | F29: 111 | G29: Brain | H29: 10 | I29: Head— unspecified | K29: Same division only | L29: No | M29: No | N29: Insufficient narrative information | O29: Part rules of selection | P29: Recorded brain (111); narrative says only 'head injury'. | Q29: An employee was walking to the break room when they slipped on a puddle of rain water on the floor and fell. The employee suffered a head injury.
A30: D029 | B30: 10 | C30: 2024087970 | D30: 2024-08-27 | E30: Secondary source | F30: 990 | G30: Source, secondary source — unspecified | H30: 991 | I30: Secondary source not applicable | K30: Same major group (2-digit) | L30: No | M30: No | N30: Insufficient narrative information | O30: Source/Secondary source rule 1 (follow the Event's "Coding interactions"; 990 vs 991) and rule 2 (whole vs part) | P30: Whether a secondary source exists (990) or not (991) cannot be determined from the narrative. | Q30: An employee was moving metal repair parts from the ground to a vehicle. The metal shifted in transit and amputated the employee's left middle fingertip.
A31: D030 | B31: 12 | C31: 2024075973 | D31: 2024-07-03 | E31: Secondary source | F31: 991 | G31: Secondary source not applicable | H31: 990 | I31: Source, secondary source— unspecified | J31: 991 | K31: Same major group (2-digit) | L31: Yes | M31: No | N31: Insufficient narrative information | O31: Source/Secondary source rule 1 (follow the Event's "Coding interactions"; 990 vs 991) and rule 2 (whole vs part) | P31: Whether a secondary source applies cannot be determined from the narrative. | Q31: An employee was installing articles of pyrotechnics when pyrotechnics misfired and blasted, resulting in injury to their hands.
A32: D031 | B32: 18 | C32: 2024021494 | D32: 2024-02-16 | E32: Part of body | F32: 51 | G32: Hip joint(s) | H32: 5861 | I32: Hip(s) and knee(s) | J32: 580, 589 | K32: Same division only | L32: No | M32: No | N32: Insufficient narrative information | O32: Part rules of selection | P32: Narrative describes two injured workers with hip and knee injuries; the recorded part covers only one injury. Cannot tell which worker the record describes. | Q32: Two employees were in a powered industrial vehicle. The vehicle hit a patch of dirt while traveling from a warehouse to a satellite camp and struck a light post. Both employees suffered injuries to the lower extremities. One employee needed stitches in their knee and hip surgery; the other employee needed stitches in their leg and hip surgery.
A33: D032 | B33: 26 | C33: 2024010166 | D33: 2024-01-08 | E33: Event/Exposure | F33: 119 | G33: Intentional violence by other person — n.e.c. | H33: 4142 | I33: Other fall to lower level— 6 to 30 feet | J33: 4122, 4140, 414 | K33: Different division | L33: No | M33: No | N33: Insufficient narrative information | O33: Event rules of selection | P33: Narrative does not state the ladder was shaken intentionally; Event 119 requires intent that the narrative does not establish. | Q33: The injured employee fell from a 10-foot step ladder that was being shaken by another employee. The employee landed on the concrete floor and suffered shoulder and head injuries.
A34: D033 | B34: 29 | C34: 2024098301 | D34: 2024-09-06 | E34: Secondary source | F34: 4216 | G34: Rods, reinforcing bar (rebar) metal | H34: 990 | I34: Source, secondary source— unspecified | J34: 991 | K34: Different division | L34: No | M34: No | N34: Insufficient narrative information | O34: Source/Secondary source rule 1 (follow the Event's "Coding interactions"; 990 vs 991) and rule 2 (whole vs part) | P34: Narrative does not identify what struck the eye; rebar as secondary source cannot be confirmed. | Q34: An employee was installing rebar when they sustained an injury to their eye.
A35: D034 | B35: 31 | C35: 2024076773 | D35: 2024-07-25 | E35: Secondary source | F35: 990 | G35: Source, secondary source — unspecified | H35: 991 | I35: Secondary source not applicable | K35: Same major group (2-digit) | L35: No | M35: No | N35: Insufficient narrative information | O35: Source/Secondary source rule 1 (follow the Event's "Coding interactions"; 990 vs 991) and rule 2 (whole vs part) | P35: Whether a secondary source applies cannot be determined. | Q35: An employee was threading film through a machine. The film got caught on the casting drum, pulling the film and employee's arm between a roller and the casting drum. The employee sustained a friction burn.
A36: D035 | B36: 38 | C36: 2024043396 | D36: 2024-04-18 | E36: Source | F36: 30 | G36: Machinery — unspecified | H36: 990 | I36: Source, secondary source— unspecified | J36: 30 | K36: Different division | L36: Yes | M36: Yes | N36: Insufficient narrative information | O36: Source/Secondary source rule 1 (follow the Event's "Coding interactions"; 990 vs 991) and rule 2 (whole vs part) | P36: Blind coder flagged this field inconclusive; narrative does not give enough detail. | Q36: On April 18, 2024, an employee was standing on equipment to clear a machine jam when his foot slipped. He suffered a severe laceration and was hospitalized. A safety railing was in place at the time of the incident.
A37: D036 | B37: 42 | C37: 2024032582 | D37: 2024-03-22 | E37: Source | F37: 10 | G37: Chemicals and hazardous materials — unspecified | H37: 4179 | I37: Garbage, recyclables, debris— n.e.c. | J37: 533, 146 | K37: Different division | L37: No | M37: No | N37: Insufficient narrative information | O37: Source/Secondary source rule 1 (follow the Event's "Coding interactions"; 990 vs 991) and rule 2 (whole vs part) | P37: Narrative says 'garbage juice or a caustic fluid'; chemical vs garbage source cannot be determined. | Q37: An employee was filling up a trailer with garbage juice and came in contact with the garbage juice or a caustic fluid, resulting in burns to the right forearm.
A38: D037 | B38: 46 | C38: 20241211275 | D38: 2024-12-06 | E38: Source | F38: 5763 | G38: Robber | H38: 570 | I38: Person, other than injured or ill worker— unspecified | J38: 576, 579 | K38: Same major group (2-digit) | L38: No | M38: No | N38: Insufficient narrative information | O38: Source/Secondary source rule 1 (follow the Event's "Coding interactions"; 990 vs 991) and rule 2 (whole vs part) | P38: Assailant motive is not stated; robber (5763) cannot be confirmed from the narrative. | Q38: An employee was acting in a loss prevention capacity when they were stabbed in the abdomen with a knife by an individual. The employee sustained multiple stab wounds, one of which punctured his lung. Part of the knife broke off in his body, requiring surgery.
A39: D038 | B39: 47 | C39: 2024098606 | D39: 2024-09-16 | E39: Part of body | F39: 6 | G39: BODY SYSTEMS | H39: 990 | I39: Part of body— unspecified | K39: Different division | L39: No | M39: Yes | N39: Insufficient narrative information | O39: Part rules of selection | P39: Blind coder flagged this field inconclusive; narrative does not give enough detail. | Q39: On September 16, 2024, an employee was hooking up a lead to a gas meter in a customer's backyard when the employee was bitten by a copperhead snake. The employee was hospitalized.
A40: D039 | B40: 53 | C40: 2024065850 | D40: 2024-06-29 | E40: Event/Exposure | F40: 5312 | G40: Exposure to environmental heat — outdoor | H40: 5310 | I40: Exposure to environmental heat— unspecified | J40: 5312, 5311, 70, 78 | K40: Same minor group (3-digit) | L40: Yes | M40: No | N40: Insufficient narrative information | O40: Event rules of selection | P40: Narrative does not state indoor/outdoor setting; recorded 5312 (outdoor) assumes it. | Q40: A vacuum truck operator was loading six pieces of aluminum pipe and three rolls of plastic flex hose onto a trailer when he started feeling overheated. The employee became ill due to heat exhaustion/dehydration.
A41: D040 | B41: 54 | C41: 2024054147 | D41: 2024-05-10 | E41: Secondary source | F41: 710 | G41: Handtools — unspecified | H41: 991 | I41: Secondary source not applicable | K41: Different division | L41: No | M41: No | N41: Insufficient narrative information | O41: Source/Secondary source rule 1 (follow the Event's "Coding interactions"; 990 vs 991) and rule 2 (whole vs part) | P41: Whether a hand tool was involved cannot be determined. | Q41: An employee was lifting a toolbox onto a cart when he felt a pull in his left wrist, resulting in a sprain/strain injury.
A42: D041 | B42: 58 | C42: 2024109805 | D42: 2024-10-21 | E42: Source | F42: 4143 | G42: Chips, pellets — metal | H42: 4417 | I42: Staples | J42: 441, 4410 | K42: Same division only | L42: No | M42: No | N42: Insufficient narrative information | O42: Source/Secondary source rule 1 (follow the Event's "Coding interactions"; 990 vs 991) and rule 2 (whole vs part) | P42: Narrative says 'a piece of metal'; staple vs metal chip cannot be determined. | Q42: An employee was assembling door jambs using a pneumatic stapler when a piece of metal was propelled into their right eye, resulting in an injury that required surgery. The employee was hospitalized.
A43: D042 | B43: 63 | C43: 20241211494 | D43: 2024-12-12 | E43: Source | F43: 6624 | G43: Other constructed surface | H43: 30 | I43: Machinery— unspecified | J43: 360 | K43: Different division | L43: No | M43: Yes | N43: Insufficient narrative information | O43: Source/Secondary source rule 1 (follow the Event's "Coding interactions"; 990 vs 991) and rule 2 (whole vs part) | P43: Blind coder flagged this field inconclusive; narrative does not give enough detail. | Q43: An employee was troubleshooting a machine when he slipped and went to brace himself. His hand entered the machine and the blade contacted his finger, resulting in a fingertip amputation.
A44: D043 | B44: 63 | C44: 20241211494 | D44: 2024-12-12 | E44: Secondary source | F44: 30 | G44: Machinery — unspecified | H44: 991 | I44: Secondary source not applicable | J44: 990 | K44: Different division | L44: No | M44: No | N44: Insufficient narrative information | O44: Source/Secondary source rule 1 (follow the Event's "Coding interactions"; 990 vs 991) and rule 2 (whole vs part) | P44: Source/secondary source depend on the event interpretation above. | Q44: An employee was troubleshooting a machine when he slipped and went to brace himself. His hand entered the machine and the blade contacted his finger, resulting in a fingertip amputation.
A45: D044 | B45: 74 | C45: 20241110591 | D45: 2024-11-13 | E45: Secondary source | F45: 990 | G45: Source, secondary source — unspecified | H45: 991 | I45: Secondary source not applicable | K45: Same major group (2-digit) | L45: No | M45: No | N45: Insufficient narrative information | O45: Source/Secondary source rule 1 (follow the Event's "Coding interactions"; 990 vs 991) and rule 2 (whole vs part) | P45: Whether a secondary source exists cannot be determined. | Q45: A employee was welding and an assistant was handing him welding rods. The welder received burns to his hands and face and was not hospitalized. The assistant received first- and second-degree burns to their hands, neck, and face that required hospitalization.
A46: D045 | B46: 83 | C46: 20241110663 | D46: 2024-11-15 | E46: Nature | F46: 1110 | G46: Intracranial injuries — unspecified | H46: 100 | I46: Traumatic injuries or exposures— unspecified | J46: 110, 1110, 1113, 134 | K46: Same division only | L46: Yes | M46: No | N46: Insufficient narrative information | O46: Nature rules of selection | P46: 'Head trauma' alone does not support 1110 intracranial injury. | Q46: An employee was manning a water pump when a vehicle came through the barriers and struck the employee. The employee fell to the ground and sustained a head trauma.
A47: D046 | B47: 83 | C47: 20241110663 | D47: 2024-11-15 | E47: Part of body | F47: 111 | G47: Brain | H47: 10 | I47: Head— unspecified | K47: Same division only | L47: No | M47: No | N47: Insufficient narrative information | O47: Part rules of selection | P47: Recorded brain (111); narrative says 'head trauma'. | Q47: An employee was manning a water pump when a vehicle came through the barriers and struck the employee. The employee fell to the ground and sustained a head trauma.
A48: D047 | B48: 85 | C48: 2024043440 | D48: 2024-04-19 | E48: Event/Exposure | F48: 4131 | G48: Fall to lower level resulting in exposure or contact — less than 6 feet | H48: 4130 | I48: Fall to lower level resulting in exposure or contact— unspecified | J48: 4131, 4132, 533, 414 | K48: Same minor group (3-digit) | L48: Yes | M48: No | N48: Insufficient narrative information | O48: Event rules of selection | P48: Fall height is not stated; <6 ft (4131) cannot be confirmed. | Q48: An employee was taking down a railing on a hot water quench tank when he fell into the tank and contacted the hot water, resulting in burns to both knees.
A49: D048 | B49: 89 | C49: 2024021811 | D49: 2024-02-28 | E49: Source | F49: 835 | G49: Motorboat, motorized yacht | H49: 830 | I49: Water vehicle— unspecified | J49: 835, 837, 839 | K49: Same major group (2-digit) | L49: Yes | M49: No | N49: Insufficient narrative information | O49: Source/Secondary source rule 1 (follow the Event's "Coding interactions"; 990 vs 991) and rule 2 (whole vs part) | P49: Narrative says 'small boat'; motorboat not stated. | Q49: An employee was leaving a work site on a barge due to adverse weather conditions. While on their way back to shore in a small boat, the boat went up a large swell and when it came back down, it went bow first into another swell and was immediately swamped. All the boat passengers fell into the river water, which was approximately 49.8 Fahrenheit. One employee was hospitalized with hypothermia.
A50: D049 | B50: 97 | C50: 2024076694 | D50: 2024-07-23 | E50: Event/Exposure | F50: 4311 | G50: Fall on same level resulting in exposure or contact | H50: 430 | I50: Slip, trip, stumble or fall on same level— fall unspecified | J50: 4311, 4312, 652, 650 | K50: Same major group (2-digit) | L50: Yes | M50: Yes | N50: Insufficient narrative information | O50: Event rules of selection | P50: Blind coder flagged this field inconclusive; narrative does not give enough detail. | Q50: An employee was cutting an 8-inch water pipe when the demolition saw blade became wedged. The employee was freeing the blade when they fell and sustained a severe laceration to their face.
...

Sheet Counts by category
A1: Category | B1: Nature | C1: Part of body | D1: Event/Exposure | E1: Source | F1: Secondary source | G1: All fields
A2: Potential discrepancy: recorded code conflicts with text | B2: =COUNTIFS('Discrepancy log'!$N$2:$N$195,$A2,'Discrepancy log'!$E$2:$E$195,"Nature") -> 1 | C2: =COUNTIFS('Discrepancy log'!$N$2:$N$195,$A2,'Discrepancy log'!$E$2:$E$195,"Part of body") -> 1 | D2: =COUNTIFS('Discrepancy log'!$N$2:$N$195,$A2,'Discrepancy log'!$E$2:$E$195,"Event/Exposure") -> 1 | E2: =COUNTIFS('Discrepancy log'!$N$2:$N$195,$A2,'Discrepancy log'!$E$2:$E$195,"Source") -> 0 | F2: =COUNTIFS('Discrepancy log'!$N$2:$N$195,$A2,'Discrepancy log'!$E$2:$E$195,"Secondary source") -> 1 | G2: =SUM(B2:F2) -> 4
A3: Potential discrepancy: recorded code less specific | B3: =COUNTIFS('Discrepancy log'!$N$2:$N$195,$A3,'Discrepancy log'!$E$2:$E$195,"Nature") -> 2 | C3: =COUNTIFS('Discrepancy log'!$N$2:$N$195,$A3,'Discrepancy log'!$E$2:$E$195,"Part of body") -> 2 | D3: =COUNTIFS('Discrepancy log'!$N$2:$N$195,$A3,'Discrepancy log'!$E$2:$E$195,"Event/Exposure") -> 7 | E3: =COUNTIFS('Discrepancy log'!$N$2:$N$195,$A3,'Discrepancy log'!$E$2:$E$195,"Source") -> 5 | F3: =COUNTIFS('Discrepancy log'!$N$2:$N$195,$A3,'Discrepancy log'!$E$2:$E$195,"Secondary source") -> 1 | G3: =SUM(B3:F3) -> 17
A4: Insufficient narrative information | B4: =COUNTIFS('Discrepancy log'!$N$2:$N$195,$A4,'Discrepancy log'!$E$2:$E$195,"Nature") -> 3 | C4: =COUNTIFS('Discrepancy log'!$N$2:$N$195,$A4,'Discrepancy log'!$E$2:$E$195,"Part of body") -> 5 | D4: =COUNTIFS('Discrepancy log'!$N$2:$N$195,$A4,'Discrepancy log'!$E$2:$E$195,"Event/Exposure") -> 5 | E4: =COUNTIFS('Discrepancy log'!$N$2:$N$195,$A4,'Discrepancy log'!$E$2:$E$195,"Source") -> 7 | F4: =COUNTIFS('Discrepancy log'!$N$2:$N$195,$A4,'Discrepancy log'!$E$2:$E$195,"Secondary source") -> 8 | G4: =SUM(B4:F4) -> 28
A5: Explained: guidance / rule-interpretation difference | B5: =COUNTIFS('Discrepancy log'!$N$2:$N$195,$A5,'Discrepancy log'!$E$2:$E$195,"Nature") -> 12 | C5: =COUNTIFS('Discrepancy log'!$N$2:$N$195,$A5,'Discrepancy log'!$E$2:$E$195,"Part of body") -> 17 | D5: =COUNTIFS('Discrepancy log'!$N$2:$N$195,$A5,'Discrepancy log'!$E$2:$E$195,"Event/Exposure") -> 25 | E5: =COUNTIFS('Discrepancy log'!$N$2:$N$195,$A5,'Discrepancy log'!$E$2:$E$195,"Source") -> 17 | F5: =COUNTIFS('Discrepancy log'!$N$2:$N$195,$A5,'Discrepancy log'!$E$2:$E$195,"Secondary source") -> 29 | G5: =SUM(B5:F5) -> 100
A6: Explained: recorded code supported on re-read | B6: =COUNTIFS('Discrepancy log'!$N$2:$N$195,$A6,'Discrepancy log'!$E$2:$E$195,"Nature") -> 10 | C6: =COUNTIFS('Discrepancy log'!$N$2:$N$195,$A6,'Discrepancy log'!$E$2:$E$195,"Part of body") -> 12 | D6: =COUNTIFS('Discrepancy log'!$N$2:$N$195,$A6,'Discrepancy log'!$E$2:$E$195,"Event/Exposure") -> 6 | E6: =COUNTIFS('Discrepancy log'!$N$2:$N$195,$A6,'Discrepancy log'!$E$2:$E$195,"Source") -> 7 | F6: =COUNTIFS('Discrepancy log'!$N$2:$N$195,$A6,'Discrepancy log'!$E$2:$E$195,"Secondary source") -> 10 | G6: =SUM(B6:F6) -> 45
A7: Total differing fields | B7: =SUM(B2:B6) -> 28 | C7: =SUM(C2:C6) -> 37 | D7: =SUM(D2:D6) -> 44 | E7: =SUM(E2:E6) -> 36 | F7: =SUM(F2:F6) -> 49 | G7: =SUM(G2:G6) -> 194
A9: Note: "Insufficient narrative information" on this sheet counts differing fields only. Fields that were inconclusive but happened to match the recorded code exactly are not in this log (they are counted in the Summary sheet of sample_review.xlsx).
