Workbook

Sheet Sample review
A1: Review ID | B1: Incident ID | C1: Event date | D1: Sampling stratum (Event division) | E1: Final narrative (line breaks removed) | F1: Nature - recorded code | G1: Nature - recorded title | H1: Part of body - recorded code | I1: Part of body - recorded title | J1: Event/Exposure - recorded code | K1: Event/Exposure - recorded title | L1: Source - recorded code | M1: Source - recorded title | N1: Secondary source - recorded code | O1: Secondary source - recorded title | P1: Nature - my code | Q1: Nature - my title | R1: Nature - my acceptable alternates | S1: Part of body - my code | T1: Part of body - my title | U1: Part of body - my acceptable alternates | V1: Event/Exposure - my code | W1: Event/Exposure - my title | X1: Event/Exposure - my acceptable alternates | Y1: Source - my code | Z1: Source - my title | AA1: Source - my acceptable alternates | AB1: Secondary source - my code | AC1: Secondary source - my title | AD1: Secondary source - my acceptable alternates | AE1: Nature - agreement status | AF1: Part of body - agreement status | AG1: Event/Exposure - agreement status | AH1: Source - agreement status | AI1: Secondary source - agreement status | AJ1: Fields I flagged inconclusive | AK1: My confidence (H/M/L) | AL1: Reviewer rationale (written blind, from narrative only) | AM1: Reviewer notes after comparison
A2: 1 | B2: 20241110833 | C2: 2024-11-20 | D2: 5 | E2: An employee was using a plasma cutter that was set up on a self-propelled track system to bevel the edge of a four-sided plate. The employee's right thigh was impaled by a piece of slag metal and he suffered burns to his right leg. | F2: 1833 | G2: Surface, flesh wounds and burns, electrical injuries | H2: 521 | I2: Thigh(s) | J2: 533 | K2: Contact with hot objects or substances | L2: 4162 | M2: Molten metal, slag | N2: 3599 | O2: Other metal, wood, and special material machinery — n.e.c. | P2: 1833 | Q2: Surface, flesh wounds and burns, electrical injuries | R2: 132, 1520, 1590 | S2: 520 | T2: Leg(s)— unspecified | U2: 521, 528 | V2: 533 | W2: Contact with hot objects or substances | X2: 6422, 642 | Y2: 4162 | Z2: Molten metal, slag | AB2: 991 | AC2: Secondary source not applicable | AE2: Exact agreement | AF2: Explained: recorded supported | AG2: Exact agreement | AH2: Exact agreement | AI2: Explained: rule interpretation | AK2: M | AL2: Slag impaled thigh (puncture) and burned leg: two natures in different groups -> multiple code. Slag both burned and impaled; Event 533 precedes 642 in order of precedence, 6422 is a defensible alternative. Slag = molten metal. | AM2: Part of body: Narrative states the right thigh was impaled; thigh (521) is supported. | Secondary source: Secondary source for the plasma-cutter track system is defensible as an item contributing to the event; narrative does not exclude it.
A3: 2 | B3: 2024087238 | C3: 2024-08-07 | D3: 7 | E3: An employee was performing skills training in the heat when they became overexerted and were hospitalized with a muscle injury. | F3: 199 | G3: Other traumatic injuries — n.e.c. | H3: 883 | I3: Body systems and other part(s) of body | J3: 738 | K3: Multiple types of bodily position and motion | L3: 562 | M3: Bodily motion or position of injured, ill worker | N3: 9542 | O3: Heat environmental | P3: 1440 | Q3: Sprains, strains, tears— unspecified | R3: 1441, 1442, 140, 1722, 1721 | S3: 990 | T3: Part of body— unspecified | U3: 888 | V3: 5310 | W3: Exposure to environmental heat— unspecified | X3: 5311, 5312, 70, 78, 739 | Y3: 9542 | Z3: Heat—environmental | AA3: 562 | AB3: 991 | AC3: Secondary source not applicable | AD3: 990 | AE3: Insufficient information | AF3: Insufficient information | AG3: Explained: rule interpretation | AH3: Explained: rule interpretation | AI3: Explained: rule interpretation | AJ3: P | AK3: L | AL3: 'Muscle injury' without body part; heat plus exertion with no location. Event 53x precedes 7x in precedence; indoor/outdoor not stated. Body part not stated. | AM3: Nature: 'Muscle injury' from heat/overexertion is not specific enough to confirm 199 vs a sprain/strain or other nature. | Part of body: Blind coder flagged this field inconclusive; narrative does not give enough detail. | Event/Exposure: Heat exposure (531x) versus overexertion/multiple body motion (738): order-of-precedence judgement under Event rule R2.b. | Source: Source follows the event chosen (bodily motion vs heat); consistent with recorded event. | Secondary source: Heat recorded as secondary source, consistent with recorded event/source pair.
A4: 3 | B4: 2024032664 | C4: 2024-03-25 | D4: 6 | E4: An employee was washing dishes when he bumped into a dishwasher that contacted him in the pelvic area and ruptured a hernia. | F4: 142 | G4: Hernias | H4: 330 | I4: Abdomen — unspecified | J4: 6652 | K4: Walked or ran into stationary object | L4: 3333 | M4: Dishwashers | N4: 991 | O4: Secondary source not applicable | P4: 142 | Q4: Hernias | S4: 340 | T4: Pelvic region— unspecified | U4: 3413, 331, 3419 | V4: 6650 | W4: Struck against stationary object— unspecified | X4: 6652, 6659, 665 | Y4: 3333 | Z4: Dishwashers | AB4: 991 | AC4: Secondary source not applicable | AE4: Exact agreement | AF4: Explained: rule interpretation | AG4: Explained: recorded supported | AH4: Exact agreement | AI4: Exact agreement | AK4: M | AL4: Hernia ruptured by contact with dishwasher at pelvic area. Contact with stationary dishwasher; walking vs. bumping not stated. | AM4: Part of body: Hernia is an abdominal-wall condition; contact was at the pelvic area. Both parts defensible (Part R2, external part). | Event/Exposure: 'Bumped into' a dishwasher fits 6652 walked/ran into stationary object.
A5: 4 | B5: 2024064855 | C5: 2024-06-03 | D5: 6 | E5: An employee was spraying vegetation around power lines where the grass was tall. He was bitten on the back of his knee by a snake. The employee was hospitalized with swelling, pain, and discoloration. | F5: 167 | G5: Allergic and irritant dermatitis — acute | H5: 523 | I5: Lower leg(s) | J5: 6210 | K5: Bitten or stung by animal — unspecified | L5: 5140 | M5: Reptiles — unspecified | N5: 549 | O5: Other plants, vegetation | P5: 167 | Q5: Allergic and irritant dermatitis— acute | R5: 160, 132, 102 | S5: 522 | T5: Knee(s) | V5: 6210 | W5: Bitten or stung by animal— unspecified | X5: 6212, 6213, 621 | Y5: 5140 | Z5: Reptiles— unspecified | AA5: 5141, 5142, 514 | AB5: 991 | AC5: Secondary source not applicable | AE5: Exact agreement | AF5: Potential: conflict | AG5: Exact agreement | AH5: Exact agreement | AI5: Explained: rule interpretation | AK5: M | AL5: Snake bite, species/venom not stated; event guidance sends unspecified bites without systemic reaction to Nature 167. Back of knee = knee. | AM5: Part of body: Narrative states bite on the back of the knee; recorded lower leg (523). | Secondary source: Tall vegetation described as the setting; recording it as secondary source is defensible.
A6: 5 | B6: 20241211148 | C6: 2024-12-03 | D6: 7 | E6: An employee was unloading boxes when they stepped back and fractured their knee. | F6: 124 | G6: Fractures | H6: 522 | I6: Knee(s) | J6: 736 | K6: Walking, without other incident | L6: 562 | M6: Bodily motion or position of injured, ill worker | N6: 991 | O6: Secondary source not applicable | P6: 124 | Q6: Fractures | S6: 522 | T6: Knee(s) | V6: 990 | W6: Event or exposure— unspecified | X6: 736, 6651, 432, 6659 | Y6: 990 | Z6: Source, secondary source— unspecified | AA6: 2112 | AB6: 990 | AC6: Source, secondary source— unspecified | AD6: 991 | AE6: Exact agreement | AF6: Exact agreement | AG6: Insufficient information | AH6: Insufficient information | AI6: Insufficient information | AJ6: E,S | AK6: L | AL6: Fractured knee but no mechanism stated (no slip, trip, fall or contact described). Event and source cannot be assigned. | AM6: Event/Exposure: Blind coder flagged this field inconclusive; narrative does not give enough detail. | Source: Blind coder flagged this field inconclusive; narrative does not give enough detail. | Secondary source: Blind coder flagged this field inconclusive; narrative does not give enough detail.
A7: 6 | B7: 2024010008 | C7: 2024-01-01 | D7: 3 | E7: An employee was inflating a tire on a flatbed trailer when the tire exploded. The rim struck the employee, resulting in a broken right arm. | F7: 124 | G7: Fractures | H7: 420 | I7: Arm(s) — unspecified | J7: 313 | K7: Explosion of pressure vessel, piping, or tire | L7: 4712 | M7: Tires, inner tubes | N7: 4713 | O7: Wheels, tire rims | P7: 124 | Q7: Fractures | S7: 420 | T7: Arm(s)— unspecified | U7: 421, 423 | V7: 313 | W7: Explosion of pressure vessel, piping, or tire | X7: 6422, 319 | Y7: 4712 | Z7: Tires, inner tubes | AA7: 4713, 4718 | AB7: 990 | AC7: Source, secondary source— unspecified | AD7: 122, 4741 | AE7: Exact agreement | AF7: Exact agreement | AG7: Exact agreement | AH7: Exact agreement | AI7: Explained: recorded supported | AK7: M | AL7: Tire exploded while being inflated; Event 6422 excludes tires/rims that exploded -> 313. Source = pressurized tire. | AM7: Secondary source: Narrative states the rim struck the worker; rim (4713) is supported.
A8: 7 | B8: 2024042890 | C8: 2024-04-02 | D8: 7 | E8: An employee was stocking customer shelves when he was getting up from the floor and lost his balance, hyperextending his left leg. This resulted in the surgical amputation of the leg above the knee. | F8: 1221 | G8: Amputations involving bone loss | H8: 521 | I8: Thigh(s) | J8: 734 | K8: Standing up, sitting down, laying down | L8: 562 | M8: Bodily motion or position of injured, ill worker | N8: 991 | O8: Secondary source not applicable | P8: 1220 | Q8: Amputations, avulsions, enucleations— unspecified | R8: 1221, 1441, 1440, 100 | S8: 520 | T8: Leg(s)— unspecified | U8: 521, 522 | V8: 734 | W8: Standing up, sitting down, laying down | X8: 432, 4319, 733, 730 | Y8: 562 | Z8: Bodily motion or position of injured, ill worker | AB8: 991 | AC8: Secondary source not applicable | AD8: 990 | AE8: Explained: recorded supported | AF8: Explained: recorded supported | AG8: Exact agreement | AH8: Exact agreement | AI8: Exact agreement | AK8: L | AL8: Surgical amputation after hyperextension while rising from floor. Initial injury type not described; amputation is the stated outcome. Rule 4(e)(2) (sequelae) argues for the initial injury but it is not specified. | AM8: Nature: Surgical above-knee amputation implies bone loss (1221). | Part of body: Amputation above the knee involves the thigh (521).
A9: 8 | B9: 2024010693 | C9: 2024-01-23 | D9: 4 | E9: An employee was walking to the break room when they slipped on a puddle of rain water on the floor and fell. The employee suffered a head injury. | F9: 110 | G9: Injuries to the brain, spinal cord — unspecified | H9: 111 | I9: Brain | J9: 4312 | K9: Fall on same level due to slip or trip | L9: 6624 | M9: Other constructed surface | N9: 9523 | O9: Rain | P9: 100 | Q9: Traumatic injuries or exposures— unspecified | R9: 110, 1113, 134, 132 | S9: 10 | T9: Head— unspecified | V9: 4312 | W9: Fall on same level due to slip or trip | X9: 4319 | Y9: 6624 | Z9: Other constructed surface | AA9: 662, 660 | AB9: 4152 | AC9: Water, liquids—nonchemical | AD9: 9520 | AE9: Insufficient information | AF9: Insufficient information | AG9: Exact agreement | AH9: Exact agreement | AI9: Explained: rule interpretation | AK9: M | AL9: Slip on rain-water puddle on floor; head injury unspecified. Surface = constructed floor; item slipped on = non-chemical liquid (wet floor). | AM9: Nature: 'Head injury' alone does not specify brain injury; recorded 110 needs detail not in the narrative. | Part of body: Recorded brain (111); narrative says only 'head injury'. | Secondary source: Rain water vs nonchemical liquid; recorded rain (9523) is defensible for a puddle of rain water.
A10: 9 | B10: 2024076056 | C10: 2024-07-06 | D10: 9 | E10: An employee was working on the sales floor when his right foot was run over by a forklift. The employee sustained a fractured little toe. | F10: 124 | G10: Fractures | H10: 542 | I10: Toes(s), toenail(s) | J10: 990 | K10: Event or exposure — unspecified | L10: 8621 | M10: Forklift, order picker, platform truck powered | N10: 991 | O10: Secondary source not applicable | P10: 124 | Q10: Fractures | S10: 542 | T10: Toes(s), toenail(s) | U10: 540, 548 | V10: 2530 | W10: Pedestrian struck by vehicle in nonroadway area— unspecified | X10: 2532, 2531, 655 | Y10: 8621 | Z10: Forklift, order picker, platform truck—powered | AA10: 862, 860 | AB10: 991 | AC10: Secondary source not applicable | AE10: Exact agreement | AF10: Exact agreement | AG10: Potential: less specific | AH10: Exact agreement | AI10: Exact agreement | AK10: M | AL10: Worker on foot run over by forklift: pedestrian event in nonroadway area (253); 655 is excluded for pedestrian incidents. Direction of travel not stated. | AM10: Event/Exposure: Narrative supports a vehicle (forklift) running over a pedestrian worker; recorded 990 is less specific.
A11: 10 | B11: 2024087970 | C11: 2024-08-27 | D11: 9 | E11: An employee was moving metal repair parts from the ground to a vehicle. The metal shifted in transit and amputated the employee's left middle fingertip. | F11: 1220 | G11: Amputations, avulsions, enucleations — unspecified | H11: 4421 | I11: Finger or thumb tip(s), nail(s) | J11: 990 | K11: Event or exposure — unspecified | L11: 40 | M11: Parts and materials — unspecified | N11: 990 | O11: Source, secondary source — unspecified | P11: 1220 | Q11: Amputations, avulsions, enucleations— unspecified | R11: 1221 | S11: 4421 | T11: Finger or thumb tip(s), nail(s) | U11: 442, 4429 | V11: 6619 | W11: Injured by object handled by person— n.e.c. | X11: 661, 663, 664, 6612, 6611 | Y11: 40 | Z11: Parts and materials— unspecified | AA11: 470, 460, 412, 499 | AB11: 991 | AC11: Secondary source not applicable | AE11: Exact agreement | AF11: Exact agreement | AG11: Potential: less specific | AH11: Exact agreement | AI11: Insufficient information | AK11: L | AL11: Fingertip amputated by shifting load of metal parts being moved by hand; event could be handled-object, shifting-object or caught-between. Source is a metal repair part (no specific code in narrative). | AM11: Event/Exposure: Narrative supports a specific event (struck by shifting object handled by worker); recorded 990 is less specific. | Secondary source: Whether a secondary source exists (990) or not (991) cannot be determined from the narrative.
A12: 11 | B12: 20241211921 | C12: 2024-12-28 | D12: 5 | E12: On December 28, 2024, an employee was adding caustic soda beads to the oven clean-in-place (CIP) cleaning system when he was splashed by hot chemicals. The employee sustained burns to his face and ear from the caustic soda beads. | F12: 1590 | G12: Other or multiple types of burns — degree unspecified | H12: 1289 | I12: Other multiple ear(s), facial locations | J12: 533 | K12: Contact with hot objects or substances | L12: 1461 | M12: Lye, alkali metal hydroxides | N12: 991 | O12: Secondary source not applicable | P12: 1510 | Q12: Chemical burns, corrosions— degree unspecified | R12: 1511, 1512, 1520 | S12: 1289 | T12: Other multiple ear(s), facial locations | U12: 120, 121 | V12: 5553 | W12: Exposure through intact tissue | X12: 5559, 555, 5550, 533 | Y12: 1461 | Z12: Lye, alkali metal hydroxides | AA12: 146 | AB12: 991 | AC12: Secondary source not applicable | AE12: Explained: rule interpretation | AF12: Exact agreement | AG12: Explained: rule interpretation | AH12: Exact agreement | AI12: Exact agreement | AK12: M | AL12: Chemical burns from caustic soda beads (Source 1461 lye/alkali hydroxides); skin contact = exposure through intact tissue. Burn degree not stated. Face plus ear = multiple ear/facial. | AM12: Nature: Hot chemical splash: Nature 1590 explicitly includes chemical and heat burns; 1510 also defensible. | Event/Exposure: Hot chemical splash: contact with hot substance (533) vs chemical exposure (555x); precedence judgement.
A13: 12 | B13: 2024075973 | C13: 2024-07-03 | D13: 3 | E13: An employee was installing articles of pyrotechnics when pyrotechnics misfired and blasted, resulting in injury to their hands. | F13: 100 | G13: Traumatic injuries or exposures — unspecified | H13: 440 | I13: Hand(s), finger(s) — unspecified | J13: 311 | K13: Intentionally set explosion | L13: 1122 | M13: Fireworks | N13: 991 | O13: Secondary source not applicable | P13: 100 | Q13: Traumatic injuries or exposures— unspecified | R13: 1520, 124, 128 | S13: 441 | T13: Hand(s), except finger(s) | U13: 440, 448 | V13: 319 | W13: Explosion— n.e.c. | X13: 31, 310, 313, 6422 | Y13: 1122 | Z13: Fireworks | AA13: 112, 782 | AB13: 990 | AC13: Source, secondary source— unspecified | AD13: 991 | AE13: Insufficient information | AF13: Explained: rule interpretation | AG13: Explained: rule interpretation | AH13: Exact agreement | AI13: Insufficient information | AJ13: N | AK13: L | AL13: Pyrotechnics misfired/blasted; injury type to hands not stated (no burn or fracture described). Explosion; source = fireworks. | AM13: Part of body: 'Hands' may or may not include fingers; 440 vs 441 depends on fuller report. | Event/Exposure: Misfired pyrotechnics: 311 (intentionally set) vs 319 depends on whether the blast was intended. | Secondary source: Whether a secondary source applies cannot be determined from the narrative.
A14: 13 | B14: 2024032393 | C14: 2024-03-18 | D14: 6 | E14: An employee was putting paper through the rolls on a machine when their gloved hand became entangled in the rollers. The employee's forearm was pulled into the machine between the belt-driven roller and a hot, steam-heated roller. The employee's right forearm sustained burn injuries that required hospitalization and surgical repair. | F14: 1520 | G14: Thermal burns — degree unspecified | H14: 423 | I14: Forearm(s) | J14: 653 | K14: Caught, entangled in running powered equipment — normal operation | L14: 360 | M14: Special process machinery — unspecified | N14: 991 | O14: Secondary source not applicable | P14: 1520 | Q14: Thermal burns— degree unspecified | R14: 1590, 1522, 1523 | S14: 423 | T14: Forearm(s) | U14: 4811 | V14: 533 | W14: Contact with hot objects or substances | X14: 653 | Y14: 3642 | Z14: Rollers, calenders, dryers—paper production | AA14: 364, 3640 | AB14: 991 | AC14: Secondary source not applicable | AD14: 3642 | AE14: Exact agreement | AF14: Exact agreement | AG14: Explained: rule interpretation | AH14: Potential: less specific | AI14: Exact agreement | AK14: M | AL14: Hand entangled in paper-machine rollers but injury described is burns from hot steam-heated roller. Entanglement initiated the chain; contact with hot roller produced the burn; 533 precedes 653 in order of precedence; 653 is a defensible alternative. Forearm burned. | AM14: Event/Exposure: Caught-in rollers vs contact with hot roller: order of precedence under Event R2.b (653 listed as an alternate). | Source: Narrative identifies paper-processing rollers; recorded 360 (special process machinery, unspecified) is less specific.
A15: 14 | B15: 2024031900 | C15: 2024-03-01 | D15: 6 | E15: An employee was using a clamp fork truck to load a railcar with rolls of material. The employee exited the lift to put a mat between two of the rolls. The roll held by the fork truck's clamp (60 inches, weighing 3,000-3,500 pounds) dropped from the clamp onto his arm, covering it from hand to bicep. He sustained compartment syndrome, with blood clots, in the arm. | F15: 199 | G15: Other traumatic injuries — n.e.c. | H15: 420 | I15: Arm(s) — unspecified | J15: 6439 | K15: Struck by other falling object — n.e.c. | L15: 2143 | M15: Reels, rolls, spools, coils | N15: 8621 | O15: Forklift, order picker, platform truck powered | P15: 103 | Q15: Nonfatal 'crushing' injuries | R15: 1232, 134, 1824, 100 | S15: 4819 | T15: Hand(s) and arm(s)— n.e.c. | U15: 4811, 428, 420 | V15: 6430 | W15: Struck by falling object— unspecified | X15: 6439, 6433, 6431 | Y15: 2143 | Z15: Reels, rolls, spools, coils | AB15: 8621 | AC15: Forklift, order picker, platform truck—powered | AD15: 3471, 991 | AE15: Explained: rule interpretation | AF15: Explained: rule interpretation | AG15: Explained: recorded supported | AH15: Exact agreement | AI15: Exact agreement | AK15: M | AL15: Roll dropped from clamp onto arm causing compartment syndrome with blood clots. Crush injury (103); alternatively vascular injury. Hand-to-bicep = hand and arm. Struck by falling object; source = roll, secondary = equipment it fell from. | AM15: Nature: Compartment syndrome after crushing; manual guidance for crush/compartment syndrome allows either coding. | Part of body: Hand-to-bicep coverage; 420 arm (unspecified) vs multiple hand/arm code. | Event/Exposure: Roll dropped from the clamp is a falling object; 6439 n.e.c. is supported.
A16: 15 | B16: 2024087923 | C16: 2024-08-27 | D16: 6 | E16: An employee was cutting trees and brush on a logging site when a tree branch (4" diameter and 10-12 feet long) fell on him. He sustained a head injury, facial trauma, fractures, blood clots and bleeding on the right side of his head. He also sustained a laceration near his temporal area and his right eye was swollen and bruised. The employee was hospitalized and required surgery. | F16: 180 | G16: Multiple traumatic injuries and disorders — unspecified | H16: 18 | I16: Multiple regions of the head | J16: 6439 | K16: Struck by other falling object — n.e.c. | L16: 5463 | M16: Limbs, branches unattached | N16: 990 | O16: Source, secondary source — unspecified | P16: 1811 | Q16: Injuries to the brain, spinal cord and severe wounds, internal injuries | R16: 181, 180, 1812, 100 | S16: 18 | T16: Multiple regions of the head | U16: 10, 19 | V16: 6439 | W16: Struck by other falling object— n.e.c. | X16: 6430, 643, 6431 | Y16: 5460 | Z16: Trees, logs, limbs— unspecified | AA16: 5461, 5469, 546 | AB16: 5461 | AC16: Trees | AD16: 5460 | AE16: Explained: rule interpretation | AF16: Exact agreement | AG16: Exact agreement | AH16: Explained: recorded supported | AI16: Explained: rule interpretation | AK16: M | AL16: Head injury with bleeding/clots, facial trauma, fractures, laceration: spans groups 11, 12, 13 -> multiple traumatic code 181x. Falling branch while cutting trees. | AM16: Nature: Multiple injuries (brain, fractures, laceration); 180 vs 1811 turns on severity guidance. | Source: Narrative says a tree branch fell on the worker; 5463 limbs/branches is more specific and supported. | Secondary source: Tree vs branch as secondary source; both appear in the narrative.
A17: 16 | B17: 2024076710 | C17: 2024-07-23 | D17: 6 | E17: An employee was cutting an iron pipe mounted on a trailer when the pipe rolled over their leg, resulting in a right tibia fracture and compartment syndrome in their lower right leg. | F17: 189 | G17: Other multiple traumatic injuries — n.e.c. | H17: 523 | I17: Lower leg(s) | J17: 663 | K17: Struck by rolling, sliding, or shifting objects non-running | L17: 4223 | M17: Pipes, tubes — metal | N17: 991 | O17: Secondary source not applicable | P17: 124 | Q17: Fractures | R17: 1824, 103 | S17: 523 | T17: Lower leg(s) | V17: 663 | W17: Struck by rolling, sliding, or shifting objects—non-running | X17: 6611, 6612, 664 | Y17: 4223 | Z17: Pipes, tubes— metal | AA17: 422 | AB17: 4741 | AC17: Vehicle trailers, trailing units | AD17: 991, 990 | AE17: Explained: recorded supported | AF17: Exact agreement | AG17: Exact agreement | AH17: Exact agreement | AI17: Explained: rule interpretation | AK17: M | AL17: Pipe rolled over leg: fracture plus compartment syndrome. Struck by rolling/shifting non-running object. Pipe was on a trailer. | AM17: Nature: Fracture plus compartment syndrome are two natures (Nature R3); a multiple-injury code is supported. | Secondary source: Trailer on which the pipe was mounted could be coded as secondary source; narrative does not require it.
A18: 17 | B18: 20241110706 | C18: 2024-11-17 | D18: 4 | E18: An employee climbed a ladder to hang a sign, lost his balance, and fell to the floor. The employee sustained back and leg injuries. | F18: 100 | G18: Traumatic injuries or exposures — unspecified | H18: 834 | I18: Trunk and other lower extremities | J18: 4140 | K18: Other fall to lower level — unspecified | L18: 730 | M18: Portable ladders and stairs — unspecified | N18: 6624 | O18: Other constructed surface | P18: 100 | Q18: Traumatic injuries or exposures— unspecified | R18: 1440, 124, 148, 180 | S18: 834 | T18: Trunk and other lower extremities | U18: 80, 899 | V18: 4140 | W18: Other fall to lower level— unspecified | X18: 4141, 4142, 4143, 410 | Y18: 730 | Z18: Portable ladders and stairs— unspecified | AA18: 731, 732, 733, 734, 739 | AB18: 6624 | AC18: Other constructed surface | AD18: 990 | AE18: Exact agreement | AF18: Exact agreement | AG18: Exact agreement | AH18: Exact agreement | AI18: Exact agreement | AK18: L | AL18: Fall from ladder, height not stated; 'back and leg injuries' with no injury type. Source ladder type not stated.
A19: 18 | B19: 2024021494 | C19: 2024-02-16 | D19: 2 | E19: Two employees were in a powered industrial vehicle. The vehicle hit a patch of dirt while traveling from a warehouse to a satellite camp and struck a light post. Both employees suffered injuries to the lower extremities. One employee needed stitches in their knee and hip surgery; the other employee needed stitches in their leg and hip surgery. | F19: 100 | G19: Traumatic injuries or exposures — unspecified | H19: 51 | I19: Hip joint(s) | J19: 2723 | K19: Collision with stationary object, nonroadway | L19: 8620 | M19: Industrial vehicle, material hauling and transport powered, unspecified | N19: 6352 | O19: Utility poles | P19: 100 | Q19: Traumatic injuries or exposures— unspecified | R19: 132, 138, 124, 182 | S19: 5861 | T19: Hip(s) and knee(s) | U19: 580, 589 | V19: 2723 | W19: Collision with stationary object, nonroadway | X19: 272, 2720, 2729 | Y19: 8620 | Z19: Industrial vehicle, material hauling and transport—powered, unspecified | AA19: 862, 860, 86 | AB19: 6353 | AC19: Road signs, poles— except utility | AD19: 6359, 6350, 224 | AE19: Insufficient information | AF19: Insufficient information | AG19: Exact agreement | AH19: Exact agreement | AI19: Explained: recorded supported | AJ19: N | AK19: L | AL19: Industrial vehicle hit dirt patch and struck a light post. Injuries: stitches (laceration) plus hip surgery (type not stated) - nature cannot be pinned down; two injured workers described in one record. | AM19: Part of body: Narrative describes two injured workers with hip and knee injuries; the recorded part covers only one injury. Cannot tell which worker the record describes. | Secondary source: Manual 6352 includes lamppost/area-lighting poles; 'light post' supports 6352.
A20: 19 | B20: 20241110374 | C20: 2024-11-06 | D20: 4 | E20: An employee was moving pallets into the freezer when they lost their footing and fell on their back. The employee sustained an injury to his upper back/lower neck area and was diagnosed with central cord syndrome. | F20: 1121 | G20: Paralysis, paraplegia, quadriplegia | H20: 21 | I20: Exterior and musculoskeletal structures of the neck | J20: 4310 | K20: Fall on same level — unspecified | L20: 6624 | M20: Other constructed surface | N20: 990 | O20: Source, secondary source — unspecified | P20: 1129 | Q20: Spinal cord injuries, paralysis— n.e.c. | R20: 1120, 1121 | S20: 821 | T20: Neck and back | U20: 21, 22, 321, 881 | V20: 4312 | W20: Fall on same level due to slip or trip | X20: 4319, 431, 4310 | Y20: 6624 | Z20: Other constructed surface | AA20: 662, 660 | AB20: 990 | AC20: Source, secondary source— unspecified | AD20: 4153, 217 | AE20: Explained: rule interpretation | AF20: Explained: rule interpretation | AG20: Explained: rule interpretation | AH20: Exact agreement | AI20: Exact agreement | AK20: M | AL20: Central cord syndrome = spinal cord injury (n.e.c.). Fall on same level after losing footing; slip vs loss of balance not clear; cause of slip not stated. | AM20: Nature: Central cord syndrome is an incomplete cord injury; 1121 vs 1129 depends on how 'paralysis' is read. | Part of body: Upper back/lower neck: 21 neck structures vs neck-and-back combination code. | Event/Exposure: 'Lost footing and fell': 4310 (unspecified) vs 4312 (slip/trip).
A21: 20 | B21: 2024010565 | C21: 2024-01-18 | D21: 6 | E21: An employee was using an industrial table saw when it amputated his thumb and caused a severe laceration to his palm. | F21: 1221 | G21: Amputations involving bone loss | H21: 4422 | I21: Thumb(s) | J21: 653 | K21: Caught, entangled in running powered equipment — normal operation | L21: 3553 | M21: Stationary saws — table | N21: 991 | O21: Secondary source not applicable | P21: 1220 | Q21: Amputations, avulsions, enucleations— unspecified | R21: 189, 1221, 1821 | S21: 448 | T21: Hand(s) and finger(s) | U21: 4422, 441, 4428 | V21: 650 | W21: Struck by running powered equipment— unspecified | X21: 659 | Y21: 3553 | Z21: Stationary saws— table | AA21: 355, 3550 | AB21: 991 | AC21: Secondary source not applicable | AE21: Explained: recorded supported | AF21: Explained: rule interpretation | AG21: Potential: conflict | AH21: Exact agreement | AI21: Exact agreement | AK21: M | AL21: Thumb amputation plus palm laceration from running table saw; amputation is the more severe injury. Thumb + palm = hand and finger. | AM21: Nature: Amputated thumb with a table saw implies bone loss; 1221 supported. | Part of body: Thumb amputation plus palm laceration: single thumb code vs multiple hand/finger code (Part R4). | Event/Exposure: Table-saw blade cutting the thumb is contact with a running blade (650/659), not being caught/entangled (653).
A22: 21 | B22: 2024032529 | C22: 2024-03-21 | D22: 4 | E22: An employee was hanging a sign on a security post at ground level in a parking lot. They turned and tripped over a curb and fell to the ground, resulting in a fractured left wrist and a laceration to the left side of the forehead. | F22: 1823 | G22: Fractures and surface, flesh wounds | H22: 813 | I22: Head and extremities | J22: 4312 | K22: Fall on same level due to slip or trip | L22: 6624 | M22: Other constructed surface | N22: 6612 | O22: Curbs | P22: 1823 | Q22: Fractures and surface, flesh wounds | R22: 124, 132 | S22: 813 | T22: Head and extremities | U22: 899, 80 | V22: 42 | W22: Slip, trip, stumble while stepping between levels | X22: 4312, 431, 4311 | Y22: 6612 | Z22: Curbs | AA22: 6623, 662, 6624 | AB22: 6624 | AC22: Other constructed surface | AD22: 991, 663 | AE22: Exact agreement | AF22: Exact agreement | AG22: Explained: rule interpretation | AH22: Explained: rule interpretation | AI22: Explained: rule interpretation | AK22: M | AL22: Tripped over a curb and fell: Event 42 includes 'tripping or falling over curbs'. Fracture plus laceration -> 1823. Wrist + forehead = head and extremities. | AM22: Event/Exposure: Manual Event 42 includes 'tripping or falling over curbs'; narrative describes a fall, supporting 4312. Both defensible. | Source: Source/secondary-source order follows the recorded event: surface fallen on vs curb tripped over. | Secondary source: As above: curb as secondary source is consistent with the recorded event 4312 guidance.
A23: 22 | B23: 2024054261 | C23: 2024-05-14 | D23: 6 | E23: An employee was operating a mower when the blade struck their foot. | F23: 100 | G23: Traumatic injuries or exposures — unspecified | H23: 540 | I23: Foot (feet), toe(s) — unspecified | J23: 659 | K23: Struck by running powered equipment — n.e.c. | L23: 3120 | M23: Mowing and brush removal machinery — unspecified | N23: 991 | O23: Secondary source not applicable | P23: 100 | Q23: Traumatic injuries or exposures— unspecified | R23: 132, 1220, 1221, 124 | S23: 540 | T23: Foot (feet), toe(s)— unspecified | U23: 541, 542 | V23: 650 | W23: Struck by running powered equipment— unspecified | X23: 659, 653 | Y23: 3120 | Z23: Mowing and brush removal machinery— unspecified | AA23: 3122, 3123, 312 | AB23: 991 | AC23: Secondary source not applicable | AE23: Insufficient information | AF23: Exact agreement | AG23: Explained: recorded supported | AH23: Exact agreement | AI23: Exact agreement | AJ23: N | AK23: L | AL23: Mower blade struck foot; no injury type stated. Struck by running powered equipment; mower type not stated. | AM23: Event/Exposure: Blade of a mower is an attached part of running equipment; 659 supported.
A24: 23 | B24: 2024054718 | C24: 2024-05-29 | D24: 2 | E24: An employee was operating a forklift when it struck a storage rack. The employee sustained a partial thumb amputation. | F24: 1220 | G24: Amputations, avulsions, enucleations — unspecified | H24: 4422 | I24: Thumb(s) | J24: 2723 | K24: Collision with stationary object, nonroadway | L24: 8621 | M24: Forklift, order picker, platform truck powered | N24: 2212 | O24: Shelves, shelving, racks | P24: 1220 | Q24: Amputations, avulsions, enucleations— unspecified | R24: 1221, 1222 | S24: 4422 | T24: Thumb(s) | U24: 442 | V24: 2723 | W24: Collision with stationary object, nonroadway | X24: 272, 664, 2720, 654 | Y24: 8621 | Z24: Forklift, order picker, platform truck—powered | AA24: 862 | AB24: 2212 | AC24: Shelves, shelving, racks | AD24: 221 | AE24: Exact agreement | AF24: Exact agreement | AG24: Exact agreement | AH24: Exact agreement | AI24: Exact agreement | AK24: L | AL24: Forklift struck a rack and thumb partially amputated; mechanism for the thumb injury not described (caught between? struck by?). Vehicle collision coded; limited by narrative.
A25: 24 | B25: 20241211261 | C25: 2024-12-05 | D25: 4 | E25: An employee was descending exterior stairs when they slipped on ice and fell to the ground. The employee sustained a sprained lower back. | F25: 1442 | G25: Sprains, strains, minor tears | H25: 322 | I25: Back — lumbar region | J25: 4140 | K25: Other fall to lower level — unspecified | L25: 6611 | M25: Stairs, steps | N25: 9521 | O25: Ice, sleet, snow, hail | P25: 1440 | Q25: Sprains, strains, tears— unspecified | R25: 1442, 1441 | S25: 322 | T25: Back— lumbar region | U25: 32, 320, 328 | V25: 4140 | W25: Other fall to lower level— unspecified | X25: 42, 4312, 4141, 4142 | Y25: 6611 | Z25: Stairs, steps | AA25: 661 | AB25: 9521 | AC25: Ice, sleet, snow, hail | AD25: 4153, 952, 9520 | AE25: Explained: recorded supported | AF25: Exact agreement | AG25: Exact agreement | AH25: Exact agreement | AI25: Exact agreement | AK25: M | AL25: Slipped on ice descending stairs and fell to the ground. Fall to lower level (stairs): Source = stairs; Secondary = ice. Sprain severity not stated. | AM25: Nature: 'Sprained lower back' fits 1442 sprain/strain.
A26: 25 | B26: 2024087345 | C26: 2024-08-10 | D26: 1 | E26: An employee was working with a client who punched the employee in the head, causing a brain injury. | F26: 1110 | G26: Intracranial injuries — unspecified | H26: 111 | I26: Brain | J26: 1142 | K26: Hitting, kicking, beating by other person while providing medical or custodial care | L26: 5732 | M26: Patient | N26: 991 | O26: Secondary source not applicable | P26: 1110 | Q26: Intracranial injuries— unspecified | R26: 110, 111, 1112, 100 | S26: 111 | T26: Brain | U26: 10, 11, 110 | V26: 1140 | W26: Hitting, kicking, beating by other person— unspecified | X26: 1142, 114, 1149 | Y26: 574 | Z26: Client or customer | AA26: 573, 5732 | AB26: 991 | AC26: Secondary source not applicable | AE26: Exact agreement | AF26: Exact agreement | AG26: Explained: rule interpretation | AH26: Explained: rule interpretation | AI26: Exact agreement | AK26: M | AL26: Punched in the head by a client; brain injury unspecified. Whether the worker was providing care not stated. | AM26: Event/Exposure: 1142 (while providing care) vs 1140 depends on whether the worker was providing care to the client. | Source: Narrative says 'client'; patient (5732) vs client (574) depends on service setting.
A27: 26 | B27: 2024010166 | C27: 2024-01-08 | D27: 1 | E27: The injured employee fell from a 10-foot step ladder that was being shaken by another employee. The employee landed on the concrete floor and suffered shoulder and head injuries. | F27: 100 | G27: Traumatic injuries or exposures — unspecified | H27: 813 | I27: Head and extremities | J27: 119 | K27: Intentional violence by other person — n.e.c. | L27: 5720 | M27: Co-worker or work associate of injured or ill worker — unspecified | N27: 733 | O27: Step ladders | P27: 100 | Q27: Traumatic injuries or exposures— unspecified | R27: 1440, 124, 110 | S27: 813 | T27: Head and extremities | U27: 81, 882 | V27: 4142 | W27: Other fall to lower level— 6 to 30 feet | X27: 4122, 4140, 414 | Y27: 733 | Z27: Step ladders | AA27: 73, 730 | AB27: 5721 | AC27: Co-worker, supervisor— current | AD27: 991 | AE27: Exact agreement | AF27: Exact agreement | AG27: Insufficient information | AH27: Explained: rule interpretation | AI27: Explained: rule interpretation | AK27: M | AL27: 10-ft fall from step ladder shaken by a co-worker; 'shoulder and head injuries' gives no injury type. Fall 6-30 ft; co-worker is the item that caused the fall. | AM27: Event/Exposure: Narrative does not state the ladder was shaken intentionally; Event 119 requires intent that the narrative does not establish. | Source: Source follows the recorded event (assailant); consistent with that choice. | Secondary source: Ladder as secondary source follows the recorded event.
A28: 27 | B28: 2024076373 | C28: 2024-07-15 | D28: 6 | E28: A panel was being lifted when an attached roller (approximately 20 pounds) slipped and fell about 2 feet onto the hard hat of an employee working below. The roller also struck the employee's shoulder and back. The employee was hospitalized and suffered a contusion to the shoulder/back. | F28: 134 | G28: Bruises, contusions | H28: 833 | I28: Trunk and other upper extremities | J28: 6430 | K28: Struck by falling object — unspecified | L28: 4644 | M28: Rollers, cylinders | N28: 3430 | O28: Elevators, hoists, lifts — unspecified | P28: 134 | Q28: Bruises, contusions | S28: 831 | T28: Back and shoulder | U28: 881 | V28: 6430 | W28: Struck by falling object— unspecified | X28: 6439, 6433 | Y28: 4644 | Z28: Rollers, cylinders | AA28: 464, 4640 | AB28: 4230 | AC28: Structural panels and sheets— unspecified | AD28: 990 | AE28: Exact agreement | AF28: Explained: rule interpretation | AG28: Exact agreement | AH28: Exact agreement | AI28: Explained: rule interpretation | AK28: L | AL28: Roller attached to a lifted panel fell about 2 ft onto head and struck shoulder/back; contusion. Source part (roller) and panel are not specifically named equipment. | AM28: Part of body: Combination-code selection for shoulder, back and hard-hat strike; depends on the full injury list. | Secondary source: Lifting equipment vs panel as secondary source; narrative supports both.
A29: 28 | B29: 20241110365 | C29: 2024-11-06 | D29: 5 | E29: On November 6, 2024, an employee was dipping parts into a hexavalent chromium bath using a crane. The employee touched their face and began to experience facial swelling, resulting in hospitalization. | F29: 102 | G29: Soreness, swelling, inflammation | H29: 120 | I29: Ears and facial region — unspecified | J29: 5553 | K29: Exposure through intact tissue | L29: 1429 | M29: Toxic metallic substances — n.e.c. | N29: 991 | O29: Secondary source not applicable | P29: 167 | Q29: Allergic and irritant dermatitis— acute | R29: 160, 1510, 102 | S29: 120 | T29: Ears and facial region— unspecified | U29: 126, 125 | V29: 5553 | W29: Exposure through intact tissue | X29: 5559, 555, 5550 | Y29: 1429 | Z29: Toxic metallic substances— n.e.c. | AA29: 142, 1420 | AB29: 991 | AC29: Secondary source not applicable | AE29: Explained: rule interpretation | AF29: Exact agreement | AG29: Exact agreement | AH29: Exact agreement | AI29: Exact agreement | AK29: M | AL29: Face contact with hexavalent chromium bath followed by facial swelling; skin reaction. Injury type (burn vs dermatitis) not stated. Chromium is listed under 1429. | AM29: Nature: Facial swelling after chromium exposure: 102 (swelling, literal) vs 167 (irritant reaction) is a rule-reading choice.
A30: 29 | B30: 2024098301 | C30: 2024-09-06 | D30: 9 | E30: An employee was installing rebar when they sustained an injury to their eye. | F30: 100 | G30: Traumatic injuries or exposures — unspecified | H30: 122 | I30: Eye(s) | J30: 990 | K30: Event or exposure — unspecified | L30: 990 | M30: Source, secondary source — unspecified | N30: 4216 | O30: Rods, reinforcing bar (rebar) metal | P30: 100 | Q30: Traumatic injuries or exposures— unspecified | R30: 1311, 132, 134 | S30: 122 | T30: Eye(s) | V30: 990 | W30: Event or exposure— unspecified | X30: 6422, 642, 6652 | Y30: 990 | Z30: Source, secondary source— unspecified | AA30: 421 | AB30: 990 | AC30: Source, secondary source— unspecified | AD30: 991 | AE30: Exact agreement | AF30: Exact agreement | AG30: Insufficient information | AH30: Insufficient information | AI30: Insufficient information | AJ30: E,S | AK30: L | AL30: Eye injury while installing rebar; no mechanism or object described (flying particle? contact?). Event and source cannot be assigned. | AM30: Secondary source: Narrative does not identify what struck the eye; rebar as secondary source cannot be confirmed.
A31: 30 | B31: 2024109442 | C31: 2024-10-10 | D31: 5 | E31: On October 10, 2024, an employee was deep cleaning operating rooms and were exposed to disinfection cleaner, resulting in an acute environmental asthma exacerbation. The employee was hospitalized. | F31: 163 | G31: Poison, toxic, or allergenic effects — other respiratory | H31: 6 | I31: BODY SYSTEMS | J31: 5531 | K31: Inhalation of harmful substance — single episode or single shift | L31: 1623 | M31: Disinfectants, detergents, soap products | N31: 991 | O31: Secondary source not applicable | P31: 163 | Q31: Poison, toxic, or allergenic effects— other respiratory | R31: 2433, 2430, 2431 | S31: 6 | T31: BODY SYSTEMS | U31: 3128, 312, 3120 | V31: 5531 | W31: Inhalation of harmful substance— single episode or single shift | X31: 5530, 553, 5532 | Y31: 1623 | Z31: Disinfectants, detergents, soap products | AA31: 162, 1620 | AB31: 5610 | AC31: Bodily conditions of injured, ill worker— unspecified | AD31: 991, 5619 | AE31: Exact agreement | AF31: Exact agreement | AG31: Exact agreement | AH31: Exact agreement | AI31: Explained: rule interpretation | AK31: M | AL31: Acute asthma exacerbation after single-episode exposure to disinfectant cleaner while cleaning operating rooms. Pre-existing asthma implied by 'exacerbation' (Nature Rule 4b: secondary source 561*). | AM31: Secondary source: Bodily condition (asthma) as secondary source is optional under guidance.
A32: 31 | B32: 2024076773 | C32: 2024-07-25 | D32: 6 | E32: An employee was threading film through a machine. The film got caught on the casting drum, pulling the film and employee's arm between a roller and the casting drum. The employee sustained a friction burn. | F32: 1591 | G32: Other or multiple types of burns — first degree | H32: 420 | I32: Arm(s) — unspecified | J32: 650 | K32: Struck by running powered equipment — unspecified | L32: 30 | M32: Machinery — unspecified | N32: 990 | O32: Source, secondary source — unspecified | P32: 133 | Q32: Abrasions | R32: 1520, 1590, 159 | S32: 420 | T32: Arm(s)— unspecified | U32: 423, 421, 428 | V32: 653 | W32: Caught, entangled in running powered equipment— normal operation | X32: 662, 654 | Y32: 3511 | Z32: Casting machinery | AA32: 351, 352, 3414, 3640 | AB32: 991 | AC32: Secondary source not applicable | AE32: Explained: rule interpretation | AF32: Exact agreement | AG32: Potential: less specific | AH32: Potential: less specific | AI32: Insufficient information | AK32: M | AL32: Arm pulled between roller and casting drum; injury was a friction burn. Nature 133 includes friction burns. Entangled in running equipment during normal operation (threading film). | AM32: Nature: Manual lists friction burns under both 133 and 1591; both defensible. | Event/Exposure: Arm pulled between roller and drum is caught/compressed in running equipment (653); recorded 650 is less specific. | Source: Narrative identifies a casting drum/film machine; recorded 30 is less specific. | Secondary source: Whether a secondary source applies cannot be determined.
A33: 32 | B33: 2024021430 | C33: 2024-02-14 | D33: 4 | E33: An employee was cutting a service line from a transformer pole to a residence's pole. He was working from a ladder secured to the pole. When the wire was cut, the release of tension caused the pole to split at ground level. The employee was strapped to the pole and fell approximately 20-25 feet to the ground. The employee suffered a brain bleed, concussion, and fractures to an orbital bone and wrist. | F33: 1112 | G33: Cerebral and other intracranial hemorrhages without skull fracture | H33: 111 | I33: Brain | J33: 4112 | K33: Fall to lower level from collapsing structure or equipment — 6 to 30 feet | L33: 6352 | M33: Utility poles | N33: 660 | O33: Ground, travel, and support surfaces — unspecified | P33: 1811 | Q33: Injuries to the brain, spinal cord and severe wounds, internal injuries | R33: 181, 180, 1111, 1112 | S33: 813 | T33: Head and extremities | U33: 81, 882 | V33: 4112 | W33: Fall to lower level from collapsing structure or equipment— 6 to 30 feet | X33: 634, 639, 4122, 4142 | Y33: 6352 | Z33: Utility poles | AA33: 635 | AB33: 990 | AC33: Source, secondary source— unspecified | AD33: 663, 731 | AE33: Explained: rule interpretation | AF33: Explained: rule interpretation | AG33: Exact agreement | AH33: Exact agreement | AI33: Explained: rule interpretation | AK33: M | AL33: Fall of about 20-25 ft when a utility pole split; brain bleed/concussion plus fractures -> multiple traumatic code. Collapsing equipment/structure fall 6-30 ft. | AM33: Nature: Brain bleed, concussion and fractures: multiple natures; 1112 vs 1811 is a precedence/severity choice. | Part of body: Head and wrist injuries: single brain code vs multi-part code (Part R4). | Secondary source: Ground as secondary source for the 20-25 ft fall is defensible.
A34: 33 | B34: 2024021550 | C34: 2024-02-19 | D34: 3 | E34: A fire involving a vacuum pump in the hospital basement caused an employee to suffer smoke inhalation. | F34: 161 | G34: Poisoning, poisoning-related asphyxia | H34: 6 | I34: BODY SYSTEMS | J34: 320 | K34: Fire — unspecified | L34: 345 | M34: Pumps — except oil well | N34: 990 | O34: Source, secondary source — unspecified | P34: 161 | Q34: Poisoning, poisoning-related asphyxia | R34: 160, 163, 185 | S34: 6 | T34: BODY SYSTEMS | U34: 3128, 312 | V34: 324 | W34: Vehicle or machinery fire | X34: 323, 320, 325 | Y34: 345 | Z34: Pumps— except oil well | AB34: 990 | AC34: Source, secondary source— unspecified | AD34: 991 | AE34: Exact agreement | AF34: Exact agreement | AG34: Potential: less specific | AH34: Exact agreement | AI34: Exact agreement | AK34: M | AL34: Smoke inhalation from fire involving a vacuum pump in a basement: Nature 161 covers smoke inhalation with no further information; fire involving machinery. | AM34: Event/Exposure: Fire involving a pump suggests machinery fire (324); recorded 320 is less specific.
A35: 34 | B35: 2024010861 | C35: 2024-01-28 | D35: 6 | E35: An employee was working at a bailer. She bent down to pick something up. As she straightened, her head struck the bailer door. She suffered a pinched nerve and a bulging disk in the lower back and was hospitalized. | F35: 2723 | G35: Disc disorders, herniated disc | H35: 322 | I35: Back — lumbar region | J35: 6653 | K35: Struck against stationary object while rising, lowering | L35: 3634 | M35: Banding, baling, strapping machinery | N35: 991 | O35: Secondary source not applicable | P35: 2723 | Q35: Disc disorders, herniated disc | R35: 146, 148, 2720 | S35: 322 | T35: Back— lumbar region | U35: 32, 320, 328 | V35: 6653 | W35: Struck against stationary object while rising, lowering | X35: 665, 6650, 733 | Y35: 3341 | Z35: Trash compactors, shredders | AA35: 334, 3340 | AB35: 991 | AC35: Secondary source not applicable | AE35: Exact agreement | AF35: Exact agreement | AG35: Exact agreement | AH35: Explained: rule interpretation | AI35: Exact agreement | AK35: M | AL35: Head struck baler door while straightening up; back injury described as pinched nerve plus bulging disc (2723 includes bulging disc and pinched nerve from herniated disc). | AM35: Source: Baler vs compactor: narrative says 'bailer' without context; both coded machines are defensible.
A36: 35 | B36: 2024109924 | C36: 2024-10-24 | D36: 3 | E36: A maintenance technician was checking the tire pressure on a debarking drum tire. They then initiated the process of adding air into the tire to the specified pounds per square inch. Within seconds, the side wall of the tire ruptured and the maintenance technician sustained broken ribs and a punctured lung. | F36: 1232 | G36: Closed trauma involving internal organs, major blood vessels | H36: 318 | I36: Multiple internal chest locations | J36: 313 | K36: Explosion of pressure vessel, piping, or tire | L36: 4712 | M36: Tires, inner tubes | N36: 346 | O36: Air compressors | P36: 1232 | Q36: Closed trauma involving internal organs, major blood vessels | R36: 124, 1231, 1238 | S36: 310 | T36: Chest— unspecified | U36: 318, 3112, 3123, 31 | V36: 313 | W36: Explosion of pressure vessel, piping, or tire | X36: 6422, 319 | Y36: 4712 | Z36: Tires, inner tubes | AA36: 4713, 4718 | AB36: 990 | AC36: Source, secondary source— unspecified | AD36: 323, 122 | AE36: Exact agreement | AF36: Explained: recorded supported | AG36: Exact agreement | AH36: Exact agreement | AI36: Explained: recorded supported | AK36: M | AL36: Tire side wall ruptured under inflation (pressure vessel/tire explosion). Rib fractures with punctured lung = 1232 (includes rib fractures with internal chest injuries). | AM36: Part of body: Broken ribs and punctured lung are internal chest locations (318). | Secondary source: Narrative says air was being added to the tire; air compressor (346) is supported.
A37: 36 | B37: 2024064961 | C37: 2024-06-05 | D37: 4 | E37: An employee was cleaning the floor when they slipped and fell to the floor, dislocating their right shoulder. | F37: 141 | G37: Dislocations | H37: 41 | I37: Shoulder(s), clavicle(s), scapula(e) | J37: 4312 | K37: Fall on same level due to slip or trip | L37: 6624 | M37: Other constructed surface | N37: 990 | O37: Source, secondary source — unspecified | P37: 141 | Q37: Dislocations | S37: 41 | T37: Shoulder(s), clavicle(s), scapula(e) | V37: 4312 | W37: Fall on same level due to slip or trip | X37: 4319, 431 | Y37: 6624 | Z37: Other constructed surface | AA37: 662, 660 | AB37: 990 | AC37: Source, secondary source— unspecified | AD37: 4152, 162 | AE37: Exact agreement | AF37: Exact agreement | AG37: Exact agreement | AH37: Exact agreement | AI37: Exact agreement | AK37: M | AL37: Slip and fall on floor while cleaning; dislocated right shoulder.
A38: 37 | B38: 2024076442 | C38: 2024-07-16 | D38: 6 | E38: An employee was stung by multiple wasps/bees after delivering a package to a home. The employee went into anaphylactic shock. | F38: 162 | G38: Anaphylactic shock, anaphylaxis | H38: 6 | I38: BODY SYSTEMS | J38: 6211 | K38: Bite or sting — insects, "bugs" | L38: 5131 | M38: Bees, hornets, wasps | N38: 991 | O38: Secondary source not applicable | P38: 162 | Q38: Anaphylactic shock, anaphylaxis | S38: 6 | T38: BODY SYSTEMS | V38: 6211 | W38: Bite or sting— insects, "bugs" | X38: 621, 6210 | Y38: 5131 | Z38: Bees, hornets, wasps | AA38: 513 | AB38: 991 | AC38: Secondary source not applicable | AE38: Exact agreement | AF38: Exact agreement | AG38: Exact agreement | AH38: Exact agreement | AI38: Exact agreement | AK38: H | AL38: Multiple wasp/bee stings with anaphylaxis: Nature 162; systemic reaction -> Part 6 (body systems).
A39: 38 | B39: 2024043396 | C39: 2024-04-18 | D39: 9 | E39: On April 18, 2024, an employee was standing on equipment to clear a machine jam when his foot slipped. He suffered a severe laceration and was hospitalized. A safety railing was in place at the time of the incident. | F39: 132 | G39: Cuts, lacerations, punctures without injury to internal structures | H39: 990 | I39: Part of body — unspecified | J39: 990 | K39: Event or exposure — unspecified | L39: 30 | M39: Machinery — unspecified | N39: 990 | O39: Source, secondary source — unspecified | P39: 132 | Q39: Cuts, lacerations, punctures without injury to internal structures | R39: 123, 1220 | S39: 990 | T39: Part of body— unspecified | V39: 990 | W39: Event or exposure— unspecified | X39: 652, 4140, 6652 | Y39: 990 | Z39: Source, secondary source— unspecified | AA39: 30 | AB39: 990 | AC39: Source, secondary source— unspecified | AD39: 991 | AE39: Exact agreement | AF39: Insufficient information | AG39: Insufficient information | AH39: Insufficient information | AI39: Exact agreement | AJ39: P,E,S | AK39: L | AL39: Foot slipped while standing on equipment clearing a jam; 'severe laceration' with no body part, no statement of what caused the cut (machine contact? fall?). Event, source and part cannot be determined. | AM39: Source: Blind coder flagged this field inconclusive; narrative does not give enough detail.
A40: 39 | B40: 2024087416 | C40: 2024-08-13 | D40: 6 | E40: An employee was pushing the door of a trailer open when a clothes dryer that was against the door fell out of the trailer. The dryer struck the employee on his hard hat and he was hospitalized and required surgery. He had neck pain, slurred speech, and sensitivity to light. | F40: 1110 | G40: Intracranial injuries — unspecified | H40: 111 | I40: Brain | J40: 6439 | K40: Struck by other falling object — n.e.c. | L40: 3332 | M40: Clothes washers, dryers | N40: 4741 | O40: Vehicle trailers, trailing units | P40: 100 | Q40: Traumatic injuries or exposures— unspecified | R40: 110, 1110, 1113 | S40: 811 | T40: Head and neck | U40: 10, 81, 821 | V40: 6430 | W40: Struck by falling object— unspecified | X40: 6432, 6439 | Y40: 3332 | Z40: Clothes washers, dryers | AA40: 333 | AB40: 4741 | AC40: Vehicle trailers, trailing units | AD40: 991 | AE40: Explained: recorded supported | AF40: Explained: recorded supported | AG40: Explained: recorded supported | AH40: Exact agreement | AI40: Exact agreement | AK40: M | AL40: Dryer fell out of trailer onto head; neck pain, slurred speech, light sensitivity but no diagnosis. Falling object; source = dryer, secondary = trailer. | AM40: Nature: Manual 1110 includes unspecified head injury with visual disturbance (light sensitivity) or slurred speech; supported. | Part of body: Brain (111) follows from the 1110 nature. | Event/Exposure: Dryer falling out of a trailer is a falling object; 6439 supported.
...

Sheet Summary
A1: Agreement summary (live formulas over the "Sample review" sheet)
A3: Field | B3: Reviewed | C3: Inconclusive at blind stage | D3: Eligible (reviewed minus inconclusive) | E3: Exact agreement (among eligible) | F3: Exact agreement % | G3: Fields in category: Exact | H3: Explained: recorded supported | I3: Explained: rule interpretation | J3: Potential: less specific | K3: Potential: conflict | L3: Insufficient information (all reasons) | M3: Check: categories sum to reviewed
A4: Nature | B4: =COUNTA('Sample review'!AE$2:AE$101) -> 100 | C4: =SUMPRODUCT(--ISNUMBER(SEARCH(",N,",","&'Sample review'!$AJ$2:$AJ$101&","))) -> 3 | D4: =B4-C4 -> 97 | E4: =SUMPRODUCT(('Sample review'!AE$2:AE$101="Exact agreement")*(1-ISNUMBER(SEARCH(",N,",","&'Sample review'!$AJ$2:$AJ$101&",")))) -> 69 | F4: =IF(D4=0,"",E4/D4) -> 0.71134021 | G4: =COUNTIF('Sample review'!AE$2:AE$101,"Exact agreement") -> 69 | H4: =COUNTIF('Sample review'!AE$2:AE$101,"Explained: recorded supported") -> 10 | I4: =COUNTIF('Sample review'!AE$2:AE$101,"Explained: rule interpretation") -> 12 | J4: =COUNTIF('Sample review'!AE$2:AE$101,"Potential: less specific") -> 2 | K4: =COUNTIF('Sample review'!AE$2:AE$101,"Potential: conflict") -> 1 | L4: =COUNTIF('Sample review'!AE$2:AE$101,"Insufficient information") -> 6 | M4: =IF(SUM(G4:L4)=B4,"OK","CHECK") -> OK
A5: Part of body | B5: =COUNTA('Sample review'!AF$2:AF$101) -> 100 | C5: =SUMPRODUCT(--ISNUMBER(SEARCH(",P,",","&'Sample review'!$AJ$2:$AJ$101&","))) -> 5 | D5: =B5-C5 -> 95 | E5: =SUMPRODUCT(('Sample review'!AF$2:AF$101="Exact agreement")*(1-ISNUMBER(SEARCH(",P,",","&'Sample review'!$AJ$2:$AJ$101&",")))) -> 60 | F5: =IF(D5=0,"",E5/D5) -> 0.63157895 | G5: =COUNTIF('Sample review'!AF$2:AF$101,"Exact agreement") -> 60 | H5: =COUNTIF('Sample review'!AF$2:AF$101,"Explained: recorded supported") -> 12 | I5: =COUNTIF('Sample review'!AF$2:AF$101,"Explained: rule interpretation") -> 17 | J5: =COUNTIF('Sample review'!AF$2:AF$101,"Potential: less specific") -> 2 | K5: =COUNTIF('Sample review'!AF$2:AF$101,"Potential: conflict") -> 1 | L5: =COUNTIF('Sample review'!AF$2:AF$101,"Insufficient information") -> 8 | M5: =IF(SUM(G5:L5)=B5,"OK","CHECK") -> OK
A6: Event/Exposure | B6: =COUNTA('Sample review'!AG$2:AG$101) -> 100 | C6: =SUMPRODUCT(--ISNUMBER(SEARCH(",E,",","&'Sample review'!$AJ$2:$AJ$101&","))) -> 5 | D6: =B6-C6 -> 95 | E6: =SUMPRODUCT(('Sample review'!AG$2:AG$101="Exact agreement")*(1-ISNUMBER(SEARCH(",E,",","&'Sample review'!$AJ$2:$AJ$101&",")))) -> 53 | F6: =IF(D6=0,"",E6/D6) -> 0.55789474 | G6: =COUNTIF('Sample review'!AG$2:AG$101,"Exact agreement") -> 53 | H6: =COUNTIF('Sample review'!AG$2:AG$101,"Explained: recorded supported") -> 6 | I6: =COUNTIF('Sample review'!AG$2:AG$101,"Explained: rule interpretation") -> 25 | J6: =COUNTIF('Sample review'!AG$2:AG$101,"Potential: less specific") -> 7 | K6: =COUNTIF('Sample review'!AG$2:AG$101,"Potential: conflict") -> 1 | L6: =COUNTIF('Sample review'!AG$2:AG$101,"Insufficient information") -> 8 | M6: =IF(SUM(G6:L6)=B6,"OK","CHECK") -> OK
A7: Source | B7: =COUNTA('Sample review'!AH$2:AH$101) -> 100 | C7: =SUMPRODUCT(--ISNUMBER(SEARCH(",S,",","&'Sample review'!$AJ$2:$AJ$101&","))) -> 6 | D7: =B7-C7 -> 94 | E7: =SUMPRODUCT(('Sample review'!AH$2:AH$101="Exact agreement")*(1-ISNUMBER(SEARCH(",S,",","&'Sample review'!$AJ$2:$AJ$101&",")))) -> 61 | F7: =IF(D7=0,"",E7/D7) -> 0.64893617 | G7: =COUNTIF('Sample review'!AH$2:AH$101,"Exact agreement") -> 61 | H7: =COUNTIF('Sample review'!AH$2:AH$101,"Explained: recorded supported") -> 7 | I7: =COUNTIF('Sample review'!AH$2:AH$101,"Explained: rule interpretation") -> 17 | J7: =COUNTIF('Sample review'!AH$2:AH$101,"Potential: less specific") -> 5 | K7: =COUNTIF('Sample review'!AH$2:AH$101,"Potential: conflict") -> 0 | L7: =COUNTIF('Sample review'!AH$2:AH$101,"Insufficient information") -> 10 | M7: =IF(SUM(G7:L7)=B7,"OK","CHECK") -> OK
A8: Secondary source | B8: =COUNTA('Sample review'!AI$2:AI$101) -> 100 | C8: =SUMPRODUCT(--ISNUMBER(SEARCH(",SS,",","&'Sample review'!$AJ$2:$AJ$101&","))) -> 0 | D8: =B8-C8 -> 100 | E8: =SUMPRODUCT(('Sample review'!AI$2:AI$101="Exact agreement")*(1-ISNUMBER(SEARCH(",SS,",","&'Sample review'!$AJ$2:$AJ$101&",")))) -> 51 | F8: =IF(D8=0,"",E8/D8) -> 0.51 | G8: =COUNTIF('Sample review'!AI$2:AI$101,"Exact agreement") -> 51 | H8: =COUNTIF('Sample review'!AI$2:AI$101,"Explained: recorded supported") -> 10 | I8: =COUNTIF('Sample review'!AI$2:AI$101,"Explained: rule interpretation") -> 29 | J8: =COUNTIF('Sample review'!AI$2:AI$101,"Potential: less specific") -> 1 | K8: =COUNTIF('Sample review'!AI$2:AI$101,"Potential: conflict") -> 1 | L8: =COUNTIF('Sample review'!AI$2:AI$101,"Insufficient information") -> 8 | M8: =IF(SUM(G8:L8)=B8,"OK","CHECK") -> OK
